I'm sorry, but an uncaught exception occurred.

While running game code:
  File "game/script.rpy", line 1707, in script
    $ intelligence_level = stats["charisma"]["level"]
  File "game/script.rpy", line 1707, in <module>
    $ intelligence_level = stats["charisma"]["level"]
KeyError: 'charisma'

-- Full Traceback ------------------------------------------------------------

Full traceback:
  File "game/script.rpy", line 1707, in script
    $ intelligence_level = stats["charisma"]["level"]
  File "D:\renpy\renpy-8.0.1-sdk\renpy\ast.py", line 823, in execute
    renpy.python.py_exec_bytecode(self.code.bytecode, self.hide, store=self.store)
  File "D:\renpy\renpy-8.0.1-sdk\renpy\python.py", line 1178, in py_exec_bytecode
    exec(bytecode, globals, locals)
  File "game/script.rpy", line 1707, in <module>
    $ intelligence_level = stats["charisma"]["level"]
KeyError: 'charisma'

Windows-10-10.0.22631 AMD64
Ren'Py 8.2.1.24030407
The Merge 1.0
Mon Jan 27 00:45:49 2025
